<mujoco>
    <option gravity="0 -9.81 0"/>
    <worldbody>
        <light diffuse=".5 .5 .5" pos="0 0 100" dir="0 0 -1"/>
        <geom type="plane" size="2.5 2.5 0.1" rgba=".9 .9 .9 1"/>
        <body name="body1" pos="0 0 0.1">
            <inertial mass="1" pos="0.5 0 0" fullinertia="1 1 0.1 0 0 0"/>
            <joint name="joint1" type="hinge" axis="0 0 1" pos="0 0 0"/>
            <geom type="box" size=".5 .05 .05" pos="0.5 0 0" rgba=".9 0 0 1"/>
            <body name="body2" pos="1.0 0 0">
                <inertial mass="1" pos="0.5 0 0" fullinertia="1 1 0.1 0 0 0"/>
                <joint name="joint2" type="hinge" axis="0 0 1" pos="0 0 0"/>
                <geom type="box" size=".5 .05 .05" pos="0.5 0 0" rgba="0 0 .9 1"/>
                <body name="body3" pos="1.0 0 0">
                    <inertial mass="0.2" pos="0.125 0 0" fullinertia="0.1 0.1 0.02 0 0 0"/>
                    <joint name="joint3" type="hinge" axis="0 0 1" pos="0 0 0"/>
                    <geom type="box" size=".125 .05 .05" pos="0.125 0 0" rgba="0 .9 0 1"/>
                    <site name="tip" pos="0.25 0 0" size="0.05" rgba="1 0 0 1"/>
                </body>
            </body>
        </body>
    </worldbody>
    <keyframe>
        <key name="home" qpos="0.5 -0.4 1.3"/>
    </keyframe>
</mujoco>